Workbook

Sheet EDT
A2: Matriz Estructura de descomposición de tareas EDT
B4: DIAS | C4: HORAS POR ACTIVIDAD O ENTREGABLE | I4: DICCIONARIO EDT
A5: Fase de Planificación | C5: Jefe de Proyecto | D5: Analista Programador | E5: DBA | F5: QA | G5: Diseñador | I5: ROL ACTOR | J5: Sigla | K5: NOMBRE ACTOR
A6: Ideas De proyecto(Primera Reunion) | B6: 1 | C6: 4 | D6: 4 | E6: 4 | F6: 4 | G6: 4 | I6: Jefe de Proyecto | J6: JP | K6: Freddy Cardenas
A7: Minuta de Reuniones | B7: 1 | C7: 7 | D7: 7 | E7: 7 | F7: 7 | G7: 7 | I7: Analista Programador | J7: AP | K7: Kevin Bustos
A8: Caso de negocios y Plan de trabajo | B8: 1 | C8: 3 | D8: 3 | E8: 3 | F8: 3 | G8: 3 | I8: Administrador BD | J8: DBA | K8: Antonio Martinez
A9: MockUps | B9: 1 | C9: 2 | D9: 1 | E9: 2 | F9: 3 | G9: 4 | I9: Calidad Y Testing | J9: QA | K9: Luis Mardones
A10: Acta de Constitucion | B10: 1 | C10: 2 | D10: 1 | E10: 2 | F10: 2 | G10: 1 | I10: Diseñador | J10: DG | K10: Mario Silva
A11: EDT(Estructura de Desglose De trabajo) | B11: 1 | C11: 1 | D11: 1 | E11: 3 | F11: 1 | G11: 2
A12: Matriz EDT | B12: 1 | C12: 2 | D12: 2 | E12: 2 | F12: 1 | G12: 1
A13: Planilla de Requerimienos | B13: 4 | C13: 2 | D13: 5 | E13: 1 | F13: 2 | G13: 2
A14: Carta Gantt | B14: 3 | C14: 2 | D14: 2 | E14: 2 | F14: 1 | G14: 1
A15: Diagrama de Casos de Uso | B15: 1 | C15: 1 | D15: 1 | E15: 2 | F15: 2 | G15: 2
A16: Documento de Casos de Uso extendido | B16: 2 | C16: 1 | D16: 2 | E16: 1 | F16: 12 | G16: 1
A17: Documentacion ERS | B17: 4 | C17: 2 | D17: 2 | E17: 2 | F17: 2 | G17: 2
A18: Presentacion 1 | B18: 1 | C18: 1 | D18: 1 | E18: 1 | F18: 1 | G18: 1
A19: Total horas Fase Planificacion | B19: =SUM(B6:B18) -> 22 | C19: =SUM(C6:C18) -> 30 | D19: =SUM(D6:D18) -> 32 | E19: =SUM(E6:E18) -> 32 | F19: =SUM(F6:F18) -> 41 | G19: =SUM(G6:G18) -> 31
A20: Fase de Desarrollo | C20: Jefe de Proyecto | D20: Analista Programador | E20: DBA | F20: QA | G20: Diseñador
A21: Matriz RACI | B21: 1 | C21: 5 | D21: 3 | E21: 2 | F21: 3 | G21: 2
A22: Matriz de Riesgos | B22: 1 | C22: 2 | D22: 2 | E22: 1 | F22: 4 | G22: 1
A23: Minuta de Reuniones | B23: 1 | C23: 5 | D23: 5 | E23: 5 | F23: 5 | G23: 5
A24: Matriz de Control de cambios | B24: 2 | C24: 2 | D24: 2 | E24: 2 | F24: 2 | G24: 2
A25: Documento de Proceso de negocios | B25: 2 | C25: 3 | D25: 3 | E25: 3 | F25: 3 | G25: 3
A26: Documento avance Spring | B26: 1 | C26: 2 | D26: 1 | E26: 2 | F26: 1 | G26: 2
A27: Diccionario de Datos | B27: 1 | C27: 5 | D27: 1 | E27: 5 | F27: 1 | G27: 1
A28: DAS(Documento Arquitectura de Sistema) | B28: 1 | C28: 2 | D28: 1 | E28: 2 | F28: 2 | G28: 1
A29: Documentos Personales | B29: 1 | C29: 1 | D29: 1 | E29: 1 | F29: 1 | G29: 1
A30: Documentos Grupales | B30: 1 | C30: 1 | D30: 1 | E30: 1 | F30: 1 | G30: 1
A31: Desarrollo Pagina Web | B31: 14 | C31: 48 | D31: 45 | E31: 46 | F31: 45 | G31: 44
A32: Desarrollo Aplicacion de Escritorio | B32: 12 | C32: 37 | D32: 38 | E32: 36 | F32: 35 | G32: 37
A33: Presentacion Fase 2 | B33: 1 | C33: 1 | D33: 1 | E33: 1 | F33: 1 | G33: 1
A34: Total horas Fase Planificacion | B34: =SUM(B21:B33) -> 39 | C34: =SUM(C21:C33) -> 114 | D34: =SUM(D21:D33) -> 104 | E34: =SUM(E21:E33) -> 107 | F34: =SUM(F21:F33) -> 104 | G34: =SUM(G21:G33) -> 101
A35: Fase de Presentacion | C35: Jefe de Proyecto | D35: Analista Programador | E35: DBA | F35: QA | G35: Diseñador
A36: Documentos Personales | B36: 1 | C36: 2 | D36: 2 | E36: 2 | F36: 2 | G36: 2
A37: Documentos Grupales | B37: 1 | C37: 2 | D37: 2 | E37: 2 | F37: 2 | G37: 2
A38: Verificacion de Alcances | B38: 2 | C38: 3 | D38: 3 | E38: 2 | F38: 3 | G38: 3
A39: Planilla de Registro de Defectos | B39: 3 | C39: 8 | D39: 8 | E39: 8 | F39: 8 | G39: 8
A40: Plan de Pruebas | B40: 6 | C40: 23 | D40: 23 | E40: 22 | F40: 25 | G40: 23
A41: Plan de Capacitacion | B41: 3 | C41: 9 | D41: 8 | E41: 7 | F41: 4 | G41: 7
A42: Matriz de Prueba BD | B42: 3 | C42: 6 | D42: 5 | E42: 6 | F42: 6 | G42: 6
...

Sheet Costos Fases
A2: SIGLA | B2: ROL | C2: NOMBRE | D2: VALOR HORA HH | E2: HORAS | F2: FASE PLANIFICACION | H2: COSTO POR HORA
A3: JP | B3: Jefe de Proyecto | C3: Freddy Cardenas | D3: 15000 | E3: =EDT!C19 -> 30 | F3: =D3*E3 -> 450000 | H3: ROL | I3: NOMBRE | J3: COSTO x HORA | K3: Sueldo mes
A4: AP | B4: Analista Programador | C4: Kevin Bustos | D4: 7000 | E4: =EDT!D19 -> 32 | F4: =D4*E4 -> 224000 | H4: Jefe de Proyecto | I4: Freddy Cardenas | J4: 15000 | K4: =F3 -> 450000
A5: DBA | B5: Desarrollador BD | C5: Antonio Martinez | D5: 9000 | E5: =EDT!E19 -> 32 | F5: =D5*E5 -> 288000 | H5: Analista Programador | I5: Kevin Bustos | J5: 7000 | K5: =F4 -> 224000
A6: QA | B6: Calidad Y Testing | C6: Luis Mardones | D6: 6000 | E6: =EDT!F19 -> 41 | F6: =D6*E6 -> 246000 | H6: Administrador BD | I6: Antonio Martinez | J6: 9000 | K6: =F5 -> 288000
A7: DG | B7: Diseñador | C7: Mario Silva | D7: 6000 | E7: =EDT!G19 -> 31 | F7: =D7*E7 -> 186000 | H7: Calidad Y Testing | I7: Luis Mardones | J7: 6000 | K7: =F6 -> 246000
B8: TOTAL FASE PLANIFICACION | F8: =SUM(F3:F7) -> 1394000 | H8: Diseñador | I8: Mario Silva | J8: 6000 | K8: =F7 -> 186000
A11: SIGLA | B11: ROL | C11: NOMBRE | D11: VALOR HORA HH | E11: HORAS | F11: FASE DISEÑO | H11: COSTO HH POR ROL
A12: JP | B12: Jefe de Proyecto | C12: Freddy Cardenas | D12: 15000 | E12: =EDT!C34 -> 114 | F12: =D12*E12 -> 1710000 | H12: Jefe de Proyecto | I12: =F3+F12+F21 -> 3225000
A13: AP | B13: Analista Programador | C13: Kevin Bustos | D13: 7000 | E13: =EDT!D34 -> 104 | F13: =D13*E13 -> 728000 | H13: Analista Programador | I13: =F4+F13+F22 -> 1428000
A14: DBA | B14: Desarrollador BD | C14: Antonio Martinez | D14: 9000 | E14: =EDT!E34 -> 107 | F14: =D14*E14 -> 963000 | H14: Administrador BD | I14: =F5+F14+F23 -> 1836000
A15: QA | B15: Calidad Y Testing | C15: Luis Mardones | D15: 6000 | E15: =EDT!F34 -> 104 | F15: =D15*E15 -> 624000 | H15: Calidad Y Testing | I15: =F6+F15+F24 -> 1254000
A16: DG | B16: Diseñador | C16: Mario Silva | D16: 6000 | E16: =EDT!G34 -> 101 | F16: =D16*E16 -> 606000 | H16: Diseñador | I16: =F7+F16+F25 -> 1224000
B17: TOTAL FASE DESARROLLO | F17: =SUM(F12:F16) -> 4631000 | H17: TOTAL HH | I17: =SUM(I12:I16) -> 8967000
A20: SIGLA | B20: ROL | C20: NOMBRE | D20: VALOR HORA HH | E20: HORAS | F20: FASE DESARROLLO | H20: COSTO POR FASE
A21: JP | B21: Jefe de Proyecto | C21: Freddy Cardenas | D21: 15000 | E21: =EDT!C48 -> 71 | F21: =D21*E21 -> 1065000 | H21: Fase de Planificación | I21: =F8 -> 1394000
A22: AP | B22: Analista Programador | C22: Kevin Bustos | D22: 7000 | E22: =EDT!D48 -> 68 | F22: =D22*E22 -> 476000 | H22: Fase de Análisis y Diseño | I22: =F17 -> 4631000
A23: DBA | B23: Desarrollador BD | C23: Antonio Martinez | D23: 9000 | E23: =EDT!E48 -> 65 | F23: =D23*E23 -> 585000 | H23: Fase de Desarrollo | I23: =F26 -> 2942000
A24: QA | B24: Calidad Y Testing | C24: Luis Mardones | D24: 6000 | E24: =EDT!F48 -> 64 | F24: =D24*E24 -> 384000 | H24: TOTAL HH FASES | I24: =SUM(I21:I23) -> 8967000
A25: DG | B25: Diseñador | C25: Mario Silva | D25: 6000 | E25: =EDT!G48 -> 72 | F25: =D25*E25 -> 432000
B26: TOTAL FASE PRESENTACION | F26: =SUM(F21:F25) -> 2942000 | H26: Costo Final del Proyecto
H27: TOTAL Costo HH | I27: =SUM(I24:I26) -> 8967000
H28: UTILIDAD + Infraestructura | I28: 870560
H29: PRECIO FINAL | I29: =I27+I28 -> 9837560
